Workbook

Sheet Categorías
A1: Categorías disponibles | B1: Tipo | D1: Meses del Año | E1: CONFIGURACIÓN DE MES
A2: Vivienda | B2: Gasto | D2: Enero | E2: Selecciona Mes de Trabajo: | F2: Enero
A3: Comida y bebida | B3: Gasto | D3: Febrero
A4: Ocio / Viajes | B4: Gasto | D4: Marzo
A5: Ocio / salidas | B5: Gasto | D5: Abril
A6: Tecnología / Otros | B6: Gasto | D6: Mayo
A7: Transporte / Gasolina | B7: Gasto | D7: Junio
A8: Ocio / Eventos | B8: Gasto | D8: Julio
A9: Salud | B9: Gasto | D9: Agosto
A10: Educación | B10: Gasto | D10: Septiembre
A11: Ropa | B11: Gasto | D11: Octubre
A12: Suscripciones | B12: Gasto | D12: Noviembre
A13: Mascotas | B13: Gasto | D13: Diciembre
A14: Otros | B14: Gasto
A15: Nómina | B15: Ingreso

Sheet Objetivo
A1: PLANIFICACIÓN DE OBJETIVOS Y SIMULACIÓN DE GASTOS ADICIONALES
A2: Simulador interactivo de patrimonio y coste de oportunidad a largo plazo (25 años)
A4: Ingresos Mensuales del Usuario | B4: 2500
A5: Gastos Mensuales Ordinarios | B5: 1500
A6: Ahorro Mensual Ordinario (Calculado) | B6: =B4-B5
A7: Gastos Adicionales Simulación (Coche/Hipoteca) | B7: 500
A8: Ahorro Mensual con Simulación (Calculado) | B8: =B6-B7
A9: Tasa de Rendimiento Anual (Inversión) | B9: 0.04
A11: Plazo Temporal | B11: Número de Meses | C11: Ahorro Ordinario Simple | D11: Patrimonio Ordinario Invertido | E11: Ahorro Simulación Simple | F11: Patrimonio Simulación Invertido | G11: Impacto Neto (Coste Oportunidad)
A12: 6 meses | B12: 6 | C12: =B$6*B12 | D12: =FV(B$9/12, B12, -B$6) | E12: =B$8*B12 | F12: =FV(B$9/12, B12, -B$8) | G12: =D12-F12
A13: 1 año | B13: 12 | C13: =B$6*B13 | D13: =FV(B$9/12, B13, -B$6) | E13: =B$8*B13 | F13: =FV(B$9/12, B13, -B$8) | G13: =D13-F13
A14: 3 años | B14: 36 | C14: =B$6*B14 | D14: =FV(B$9/12, B14, -B$6) | E14: =B$8*B14 | F14: =FV(B$9/12, B14, -B$8) | G14: =D14-F14
A15: 5 años | B15: 60 | C15: =B$6*B15 | D15: =FV(B$9/12, B15, -B$6) | E15: =B$8*B15 | F15: =FV(B$9/12, B15, -B$8) | G15: =D15-F15
A16: 10 años | B16: 120 | C16: =B$6*B16 | D16: =FV(B$9/12, B16, -B$6) | E16: =B$8*B16 | F16: =FV(B$9/12, B16, -B$8) | G16: =D16-F16
A17: 25 años | B17: 300 | C17: =B$6*B17 | D17: =FV(B$9/12, B17, -B$6) | E17: =B$8*B17 | F17: =FV(B$9/12, B17, -B$8) | G17: =D17-F17

Sheet Cuadro de Mando
B1: CUADRO DE MANDO FINANCIERO PERSONAL INTERACTIVO
B2: Perspectiva de Analista Financiero - Actualizado a 21/05/2026 | R2: Mes | S2: Ingresos | T2: Gastos | U2: Ahorro Neto | V2: Tasa de Ahorro | W2: Vivienda | X2: Comida y bebida | Y2: Ocio / Viajes | Z2: Ocio / salidas | AA2: Tecnología / Otros | AB2: Transporte / Gasolina | AC2: Ocio / Eventos | AD2: Salud | AE2: Educación | AF2: Ropa | AG2: Suscripciones | AH2: Mascotas | AI2: Otros
B3: Seleccione Año de Análisis: | C3: 2026 | R3: Enero | S3: =IF(INDIRECT("'Resumen Mensual "&$C$3&"'!B"&3)="","",INDIRECT("'Resumen Mensual "&$C$3&"'!B"&3)) | T3: =IF(INDIRECT("'Resumen Mensual "&$C$3&"'!C"&3)="","",INDIRECT("'Resumen Mensual "&$C$3&"'!C"&3)) | U3: =IF(INDIRECT("'Resumen Mensual "&$C$3&"'!D"&3)="","",INDIRECT("'Resumen Mensual "&$C$3&"'!D"&3)) | V3: =IF(INDIRECT("'Resumen Mensual "&$C$3&"'!E"&3)="","",INDIRECT("'Resumen Mensual "&$C$3&"'!E"&3)) | W3: =IF(INDIRECT("'Resumen Mensual "&$C$3&"'!F"&3)="","",INDIRECT("'Resumen Mensual "&$C$3&"'!F"&3)) | X3: =IF(INDIRECT("'Resumen Mensual "&$C$3&"'!G"&3)="","",INDIRECT("'Resumen Mensual "&$C$3&"'!G"&3)) | Y3: =IF(INDIRECT("'Resumen Mensual "&$C$3&"'!H"&3)="","",INDIRECT("'Resumen Mensual "&$C$3&"'!H"&3)) | Z3: =IF(INDIRECT("'Resumen Mensual "&$C$3&"'!I"&3)="","",INDIRECT("'Resumen Mensual "&$C$3&"'!I"&3)) | AA3: =IF(INDIRECT("'Resumen Mensual "&$C$3&"'!J"&3)="","",INDIRECT("'Resumen Mensual "&$C$3&"'!J"&3)) | AB3: =IF(INDIRECT("'Resumen Mensual "&$C$3&"'!K"&3)="","",INDIRECT("'Resumen Mensual "&$C$3&"'!K"&3)) | AC3: =IF(INDIRECT("'Resumen Mensual "&$C$3&"'!L"&3)="","",INDIRECT("'Resumen Mensual "&$C$3&"'!L"&3)) | AD3: =IF(INDIRECT("'Resumen Mensual "&$C$3&"'!M"&3)="","",INDIRECT("'Resumen Mensual "&$C$3&"'!M"&3)) | AE3: =IF(INDIRECT("'Resumen Mensual "&$C$3&"'!N"&3)="","",INDIRECT("'Resumen Mensual "&$C$3&"'!N"&3)) | AF3: =IF(INDIRECT("'Resumen Mensual "&$C$3&"'!O"&3)="","",INDIRECT("'Resumen Mensual "&$C$3&"'!O"&3)) | AG3: =IF(INDIRECT("'Resumen Mensual "&$C$3&"'!P"&3)="","",INDIRECT("'Resumen Mensual "&$C$3&"'!P"&3)) | AH3: =IF(INDIRECT("'Resumen Mensual "&$C$3&"'!Q"&3)="","",INDIRECT("'Resumen Mensual "&$C$3&"'!Q"&3)) | AI3: =IF(INDIRECT("'Resumen Mensual "&$C$3&"'!R"&3)="","",INDIRECT("'Resumen Mensual "&$C$3&"'!R"&3))
B4: INGRESOS ACUMULADOS | F4: GASTOS ACUMULADOS | J4: AHORRO NETO ACUMULADO | N4: TASA DE AHORRO PROMEDIO | R4: Febrero | S4: =IF(INDIRECT("'Resumen Mensual "&$C$3&"'!B"&4)="","",INDIRECT("'Resumen Mensual "&$C$3&"'!B"&4)) | T4: =IF(INDIRECT("'Resumen Mensual "&$C$3&"'!C"&4)="","",INDIRECT("'Resumen Mensual "&$C$3&"'!C"&4)) | U4: =IF(INDIRECT("'Resumen Mensual "&$C$3&"'!D"&4)="","",INDIRECT("'Resumen Mensual "&$C$3&"'!D"&4)) | V4: =IF(INDIRECT("'Resumen Mensual "&$C$3&"'!E"&4)="","",INDIRECT("'Resumen Mensual "&$C$3&"'!E"&4)) | W4: =IF(INDIRECT("'Resumen Mensual "&$C$3&"'!F"&4)="","",INDIRECT("'Resumen Mensual "&$C$3&"'!F"&4)) | X4: =IF(INDIRECT("'Resumen Mensual "&$C$3&"'!G"&4)="","",INDIRECT("'Resumen Mensual "&$C$3&"'!G"&4)) | Y4: =IF(INDIRECT("'Resumen Mensual "&$C$3&"'!H"&4)="","",INDIRECT("'Resumen Mensual "&$C$3&"'!H"&4)) | Z4: =IF(INDIRECT("'Resumen Mensual "&$C$3&"'!I"&4)="","",INDIRECT("'Resumen Mensual "&$C$3&"'!I"&4)) | AA4: =IF(INDIRECT("'Resumen Mensual "&$C$3&"'!J"&4)="","",INDIRECT("'Resumen Mensual "&$C$3&"'!J"&4)) | AB4: =IF(INDIRECT("'Resumen Mensual "&$C$3&"'!K"&4)="","",INDIRECT("'Resumen Mensual "&$C$3&"'!K"&4)) | AC4: =IF(INDIRECT("'Resumen Mensual "&$C$3&"'!L"&4)="","",INDIRECT("'Resumen Mensual "&$C$3&"'!L"&4)) | AD4: =IF(INDIRECT("'Resumen Mensual "&$C$3&"'!M"&4)="","",INDIRECT("'Resumen Mensual "&$C$3&"'!M"&4)) | AE4: =IF(INDIRECT("'Resumen Mensual "&$C$3&"'!N"&4)="","",INDIRECT("'Resumen Mensual "&$C$3&"'!N"&4)) | AF4: =IF(INDIRECT("'Resumen Mensual "&$C$3&"'!O"&4)="","",INDIRECT("'Resumen Mensual "&$C$3&"'!O"&4)) | AG4: =IF(INDIRECT("'Resumen Mensual "&$C$3&"'!P"&4)="","",INDIRECT("'Resumen Mensual "&$C$3&"'!P"&4)) | AH4: =IF(INDIRECT("'Resumen Mensual "&$C$3&"'!Q"&4)="","",INDIRECT("'Resumen Mensual "&$C$3&"'!Q"&4)) | AI4: =IF(INDIRECT("'Resumen Mensual "&$C$3&"'!R"&4)="","",INDIRECT("'Resumen Mensual "&$C$3&"'!R"&4))
B5: =S15 | F5: =T15 | J5: =U15 | N5: =V15 | R5: Marzo | S5: =IF(INDIRECT("'Resumen Mensual "&$C$3&"'!B"&5)="","",INDIRECT("'Resumen Mensual "&$C$3&"'!B"&5)) | T5: =IF(INDIRECT("'Resumen Mensual "&$C$3&"'!C"&5)="","",INDIRECT("'Resumen Mensual "&$C$3&"'!C"&5)) | U5: =IF(INDIRECT("'Resumen Mensual "&$C$3&"'!D"&5)="","",INDIRECT("'Resumen Mensual "&$C$3&"'!D"&5)) | V5: =IF(INDIRECT("'Resumen Mensual "&$C$3&"'!E"&5)="","",INDIRECT("'Resumen Mensual "&$C$3&"'!E"&5)) | W5: =IF(INDIRECT("'Resumen Mensual "&$C$3&"'!F"&5)="","",INDIRECT("'Resumen Mensual "&$C$3&"'!F"&5)) | X5: =IF(INDIRECT("'Resumen Mensual "&$C$3&"'!G"&5)="","",INDIRECT("'Resumen Mensual "&$C$3&"'!G"&5)) | Y5: =IF(INDIRECT("'Resumen Mensual "&$C$3&"'!H"&5)="","",INDIRECT("'Resumen Mensual "&$C$3&"'!H"&5)) | Z5: =IF(INDIRECT("'Resumen Mensual "&$C$3&"'!I"&5)="","",INDIRECT("'Resumen Mensual "&$C$3&"'!I"&5)) | AA5: =IF(INDIRECT("'Resumen Mensual "&$C$3&"'!J"&5)="","",INDIRECT("'Resumen Mensual "&$C$3&"'!J"&5)) | AB5: =IF(INDIRECT("'Resumen Mensual "&$C$3&"'!K"&5)="","",INDIRECT("'Resumen Mensual "&$C$3&"'!K"&5)) | AC5: =IF(INDIRECT("'Resumen Mensual "&$C$3&"'!L"&5)="","",INDIRECT("'Resumen Mensual "&$C$3&"'!L"&5)) | AD5: =IF(INDIRECT("'Resumen Mensual "&$C$3&"'!M"&5)="","",INDIRECT("'Resumen Mensual "&$C$3&"'!M"&5)) | AE5: =IF(INDIRECT("'Resumen Mensual "&$C$3&"'!N"&5)="","",INDIRECT("'Resumen Mensual "&$C$3&"'!N"&5)) | AF5: =IF(INDIRECT("'Resumen Mensual "&$C$3&"'!O"&5)="","",INDIRECT("'Resumen Mensual "&$C$3&"'!O"&5)) | AG5: =IF(INDIRECT("'Resumen Mensual "&$C$3&"'!P"&5)="","",INDIRECT("'Resumen Mensual "&$C$3&"'!P"&5)) | AH5: =IF(INDIRECT("'Resumen Mensual "&$C$3&"'!Q"&5)="","",INDIRECT("'Resumen Mensual "&$C$3&"'!Q"&5)) | AI5: =IF(INDIRECT("'Resumen Mensual "&$C$3&"'!R"&5)="","",INDIRECT("'Resumen Mensual "&$C$3&"'!R"&5))
R6: Abril | S6: =IF(INDIRECT("'Resumen Mensual "&$C$3&"'!B"&6)="","",INDIRECT("'Resumen Mensual "&$C$3&"'!B"&6)) | T6: =IF(INDIRECT("'Resumen Mensual "&$C$3&"'!C"&6)="","",INDIRECT("'Resumen Mensual "&$C$3&"'!C"&6)) | U6: =IF(INDIRECT("'Resumen Mensual "&$C$3&"'!D"&6)="","",INDIRECT("'Resumen Mensual "&$C$3&"'!D"&6)) | V6: =IF(INDIRECT("'Resumen Mensual "&$C$3&"'!E"&6)="","",INDIRECT("'Resumen Mensual "&$C$3&"'!E"&6)) | W6: =IF(INDIRECT("'Resumen Mensual "&$C$3&"'!F"&6)="","",INDIRECT("'Resumen Mensual "&$C$3&"'!F"&6)) | X6: =IF(INDIRECT("'Resumen Mensual "&$C$3&"'!G"&6)="","",INDIRECT("'Resumen Mensual "&$C$3&"'!G"&6)) | Y6: =IF(INDIRECT("'Resumen Mensual "&$C$3&"'!H"&6)="","",INDIRECT("'Resumen Mensual "&$C$3&"'!H"&6)) | Z6: =IF(INDIRECT("'Resumen Mensual "&$C$3&"'!I"&6)="","",INDIRECT("'Resumen Mensual "&$C$3&"'!I"&6)) | AA6: =IF(INDIRECT("'Resumen Mensual "&$C$3&"'!J"&6)="","",INDIRECT("'Resumen Mensual "&$C$3&"'!J"&6)) | AB6: =IF(INDIRECT("'Resumen Mensual "&$C$3&"'!K"&6)="","",INDIRECT("'Resumen Mensual "&$C$3&"'!K"&6)) | AC6: =IF(INDIRECT("'Resumen Mensual "&$C$3&"'!L"&6)="","",INDIRECT("'Resumen Mensual "&$C$3&"'!L"&6)) | AD6: =IF(INDIRECT("'Resumen Mensual "&$C$3&"'!M"&6)="","",INDIRECT("'Resumen Mensual "&$C$3&"'!M"&6)) | AE6: =IF(INDIRECT("'Resumen Mensual "&$C$3&"'!N"&6)="","",INDIRECT("'Resumen Mensual "&$C$3&"'!N"&6)) | AF6: =IF(INDIRECT("'Resumen Mensual "&$C$3&"'!O"&6)="","",INDIRECT("'Resumen Mensual "&$C$3&"'!O"&6)) | AG6: =IF(INDIRECT("'Resumen Mensual "&$C$3&"'!P"&6)="","",INDIRECT("'Resumen Mensual "&$C$3&"'!P"&6)) | AH6: =IF(INDIRECT("'Resumen Mensual "&$C$3&"'!Q"&6)="","",INDIRECT("'Resumen Mensual "&$C$3&"'!Q"&6)) | AI6: =IF(INDIRECT("'Resumen Mensual "&$C$3&"'!R"&6)="","",INDIRECT("'Resumen Mensual "&$C$3&"'!R"&6))
R7: Mayo | S7: =IF(INDIRECT("'Resumen Mensual "&$C$3&"'!B"&7)="","",INDIRECT("'Resumen Mensual "&$C$3&"'!B"&7)) | T7: =IF(INDIRECT("'Resumen Mensual "&$C$3&"'!C"&7)="","",INDIRECT("'Resumen Mensual "&$C$3&"'!C"&7)) | U7: =IF(INDIRECT("'Resumen Mensual "&$C$3&"'!D"&7)="","",INDIRECT("'Resumen Mensual "&$C$3&"'!D"&7)) | V7: =IF(INDIRECT("'Resumen Mensual "&$C$3&"'!E"&7)="","",INDIRECT("'Resumen Mensual "&$C$3&"'!E"&7)) | W7: =IF(INDIRECT("'Resumen Mensual "&$C$3&"'!F"&7)="","",INDIRECT("'Resumen Mensual "&$C$3&"'!F"&7)) | X7: =IF(INDIRECT("'Resumen Mensual "&$C$3&"'!G"&7)="","",INDIRECT("'Resumen Mensual "&$C$3&"'!G"&7)) | Y7: =IF(INDIRECT("'Resumen Mensual "&$C$3&"'!H"&7)="","",INDIRECT("'Resumen Mensual "&$C$3&"'!H"&7)) | Z7: =IF(INDIRECT("'Resumen Mensual "&$C$3&"'!I"&7)="","",INDIRECT("'Resumen Mensual "&$C$3&"'!I"&7)) | AA7: =IF(INDIRECT("'Resumen Mensual "&$C$3&"'!J"&7)="","",INDIRECT("'Resumen Mensual "&$C$3&"'!J"&7)) | AB7: =IF(INDIRECT("'Resumen Mensual "&$C$3&"'!K"&7)="","",INDIRECT("'Resumen Mensual "&$C$3&"'!K"&7)) | AC7: =IF(INDIRECT("'Resumen Mensual "&$C$3&"'!L"&7)="","",INDIRECT("'Resumen Mensual "&$C$3&"'!L"&7)) | AD7: =IF(INDIRECT("'Resumen Mensual "&$C$3&"'!M"&7)="","",INDIRECT("'Resumen Mensual "&$C$3&"'!M"&7)) | AE7: =IF(INDIRECT("'Resumen Mensual "&$C$3&"'!N"&7)="","",INDIRECT("'Resumen Mensual "&$C$3&"'!N"&7)) | AF7: =IF(INDIRECT("'Resumen Mensual "&$C$3&"'!O"&7)="","",INDIRECT("'Resumen Mensual "&$C$3&"'!O"&7)) | AG7: =IF(INDIRECT("'Resumen Mensual "&$C$3&"'!P"&7)="","",INDIRECT("'Resumen Mensual "&$C$3&"'!P"&7)) | AH7: =IF(INDIRECT("'Resumen Mensual "&$C$3&"'!Q"&7)="","",INDIRECT("'Resumen Mensual "&$C$3&"'!Q"&7)) | AI7: =IF(INDIRECT("'Resumen Mensual "&$C$3&"'!R"&7)="","",INDIRECT("'Resumen Mensual "&$C$3&"'!R"&7))
R8: Junio | S8: =IF(INDIRECT("'Resumen Mensual "&$C$3&"'!B"&8)="","",INDIRECT("'Resumen Mensual "&$C$3&"'!B"&8)) | T8: =IF(INDIRECT("'Resumen Mensual "&$C$3&"'!C"&8)="","",INDIRECT("'Resumen Mensual "&$C$3&"'!C"&8)) | U8: =IF(INDIRECT("'Resumen Mensual "&$C$3&"'!D"&8)="","",INDIRECT("'Resumen Mensual "&$C$3&"'!D"&8)) | V8: =IF(INDIRECT("'Resumen Mensual "&$C$3&"'!E"&8)="","",INDIRECT("'Resumen Mensual "&$C$3&"'!E"&8)) | W8: =IF(INDIRECT("'Resumen Mensual "&$C$3&"'!F"&8)="","",INDIRECT("'Resumen Mensual "&$C$3&"'!F"&8)) | X8: =IF(INDIRECT("'Resumen Mensual "&$C$3&"'!G"&8)="","",INDIRECT("'Resumen Mensual "&$C$3&"'!G"&8)) | Y8: =IF(INDIRECT("'Resumen Mensual "&$C$3&"'!H"&8)="","",INDIRECT("'Resumen Mensual "&$C$3&"'!H"&8)) | Z8: =IF(INDIRECT("'Resumen Mensual "&$C$3&"'!I"&8)="","",INDIRECT("'Resumen Mensual "&$C$3&"'!I"&8)) | AA8: =IF(INDIRECT("'Resumen Mensual "&$C$3&"'!J"&8)="","",INDIRECT("'Resumen Mensual "&$C$3&"'!J"&8)) | AB8: =IF(INDIRECT("'Resumen Mensual "&$C$3&"'!K"&8)="","",INDIRECT("'Resumen Mensual "&$C$3&"'!K"&8)) | AC8: =IF(INDIRECT("'Resumen Mensual "&$C$3&"'!L"&8)="","",INDIRECT("'Resumen Mensual "&$C$3&"'!L"&8)) | AD8: =IF(INDIRECT("'Resumen Mensual "&$C$3&"'!M"&8)="","",INDIRECT("'Resumen Mensual "&$C$3&"'!M"&8)) | AE8: =IF(INDIRECT("'Resumen Mensual "&$C$3&"'!N"&8)="","",INDIRECT("'Resumen Mensual "&$C$3&"'!N"&8)) | AF8: =IF(INDIRECT("'Resumen Mensual "&$C$3&"'!O"&8)="","",INDIRECT("'Resumen Mensual "&$C$3&"'!O"&8)) | AG8: =IF(INDIRECT("'Resumen Mensual "&$C$3&"'!P"&8)="","",INDIRECT("'Resumen Mensual "&$C$3&"'!P"&8)) | AH8: =IF(INDIRECT("'Resumen Mensual "&$C$3&"'!Q"&8)="","",INDIRECT("'Resumen Mensual "&$C$3&"'!Q"&8)) | AI8: =IF(INDIRECT("'Resumen Mensual "&$C$3&"'!R"&8)="","",INDIRECT("'Resumen Mensual "&$C$3&"'!R"&8))
R9: Julio | S9: =IF(INDIRECT("'Resumen Mensual "&$C$3&"'!B"&9)="","",INDIRECT("'Resumen Mensual "&$C$3&"'!B"&9)) | T9: =IF(INDIRECT("'Resumen Mensual "&$C$3&"'!C"&9)="","",INDIRECT("'Resumen Mensual "&$C$3&"'!C"&9)) | U9: =IF(INDIRECT("'Resumen Mensual "&$C$3&"'!D"&9)="","",INDIRECT("'Resumen Mensual "&$C$3&"'!D"&9)) | V9: =IF(INDIRECT("'Resumen Mensual "&$C$3&"'!E"&9)="","",INDIRECT("'Resumen Mensual "&$C$3&"'!E"&9)) | W9: =IF(INDIRECT("'Resumen Mensual "&$C$3&"'!F"&9)="","",INDIRECT("'Resumen Mensual "&$C$3&"'!F"&9)) | X9: =IF(INDIRECT("'Resumen Mensual "&$C$3&"'!G"&9)="","",INDIRECT("'Resumen Mensual "&$C$3&"'!G"&9)) | Y9: =IF(INDIRECT("'Resumen Mensual "&$C$3&"'!H"&9)="","",INDIRECT("'Resumen Mensual "&$C$3&"'!H"&9)) | Z9: =IF(INDIRECT("'Resumen Mensual "&$C$3&"'!I"&9)="","",INDIRECT("'Resumen Mensual "&$C$3&"'!I"&9)) | AA9: =IF(INDIRECT("'Resumen Mensual "&$C$3&"'!J"&9)="","",INDIRECT("'Resumen Mensual "&$C$3&"'!J"&9)) | AB9: =IF(INDIRECT("'Resumen Mensual "&$C$3&"'!K"&9)="","",INDIRECT("'Resumen Mensual "&$C$3&"'!K"&9)) | AC9: =IF(INDIRECT("'Resumen Mensual "&$C$3&"'!L"&9)="","",INDIRECT("'Resumen Mensual "&$C$3&"'!L"&9)) | AD9: =IF(INDIRECT("'Resumen Mensual "&$C$3&"'!M"&9)="","",INDIRECT("'Resumen Mensual "&$C$3&"'!M"&9)) | AE9: =IF(INDIRECT("'Resumen Mensual "&$C$3&"'!N"&9)="","",INDIRECT("'Resumen Mensual "&$C$3&"'!N"&9)) | AF9: =IF(INDIRECT("'Resumen Mensual "&$C$3&"'!O"&9)="","",INDIRECT("'Resumen Mensual "&$C$3&"'!O"&9)) | AG9: =IF(INDIRECT("'Resumen Mensual "&$C$3&"'!P"&9)="","",INDIRECT("'Resumen Mensual "&$C$3&"'!P"&9)) | AH9: =IF(INDIRECT("'Resumen Mensual "&$C$3&"'!Q"&9)="","",INDIRECT("'Resumen Mensual "&$C$3&"'!Q"&9)) | AI9: =IF(INDIRECT("'Resumen Mensual "&$C$3&"'!R"&9)="","",INDIRECT("'Resumen Mensual "&$C$3&"'!R"&9))
R10: Agosto | S10: =IF(INDIRECT("'Resumen Mensual "&$C$3&"'!B"&10)="","",INDIRECT("'Resumen Mensual "&$C$3&"'!B"&10)) | T10: =IF(INDIRECT("'Resumen Mensual "&$C$3&"'!C"&10)="","",INDIRECT("'Resumen Mensual "&$C$3&"'!C"&10)) | U10: =IF(INDIRECT("'Resumen Mensual "&$C$3&"'!D"&10)="","",INDIRECT("'Resumen Mensual "&$C$3&"'!D"&10)) | V10: =IF(INDIRECT("'Resumen Mensual "&$C$3&"'!E"&10)="","",INDIRECT("'Resumen Mensual "&$C$3&"'!E"&10)) | W10: =IF(INDIRECT("'Resumen Mensual "&$C$3&"'!F"&10)="","",INDIRECT("'Resumen Mensual "&$C$3&"'!F"&10)) | X10: =IF(INDIRECT("'Resumen Mensual "&$C$3&"'!G"&10)="","",INDIRECT("'Resumen Mensual "&$C$3&"'!G"&10)) | Y10: =IF(INDIRECT("'Resumen Mensual "&$C$3&"'!H"&10)="","",INDIRECT("'Resumen Mensual "&$C$3&"'!H"&10)) | Z10: =IF(INDIRECT("'Resumen Mensual "&$C$3&"'!I"&10)="","",INDIRECT("'Resumen Mensual "&$C$3&"'!I"&10)) | AA10: =IF(INDIRECT("'Resumen Mensual "&$C$3&"'!J"&10)="","",INDIRECT("'Resumen Mensual "&$C$3&"'!J"&10)) | AB10: =IF(INDIRECT("'Resumen Mensual "&$C$3&"'!K"&10)="","",INDIRECT("'Resumen Mensual "&$C$3&"'!K"&10)) | AC10: =IF(INDIRECT("'Resumen Mensual "&$C$3&"'!L"&10)="","",INDIRECT("'Resumen Mensual "&$C$3&"'!L"&10)) | AD10: =IF(INDIRECT("'Resumen Mensual "&$C$3&"'!M"&10)="","",INDIRECT("'Resumen Mensual "&$C$3&"'!M"&10)) | AE10: =IF(INDIRECT("'Resumen Mensual "&$C$3&"'!N"&10)="","",INDIRECT("'Resumen Mensual "&$C$3&"'!N"&10)) | AF10: =IF(INDIRECT("'Resumen Mensual "&$C$3&"'!O"&10)="","",INDIRECT("'Resumen Mensual "&$C$3&"'!O"&10)) | AG10: =IF(INDIRECT("'Resumen Mensual "&$C$3&"'!P"&10)="","",INDIRECT("'Resumen Mensual "&$C$3&"'!P"&10)) | AH10: =IF(INDIRECT("'Resumen Mensual "&$C$3&"'!Q"&10)="","",INDIRECT("'Resumen Mensual "&$C$3&"'!Q"&10)) | AI10: =IF(INDIRECT("'Resumen Mensual "&$C$3&"'!R"&10)="","",INDIRECT("'Resumen Mensual "&$C$3&"'!R"&10))
R11: Septiembre | S11: =IF(INDIRECT("'Resumen Mensual "&$C$3&"'!B"&11)="","",INDIRECT("'Resumen Mensual "&$C$3&"'!B"&11)) | T11: =IF(INDIRECT("'Resumen Mensual "&$C$3&"'!C"&11)="","",INDIRECT("'Resumen Mensual "&$C$3&"'!C"&11)) | U11: =IF(INDIRECT("'Resumen Mensual "&$C$3&"'!D"&11)="","",INDIRECT("'Resumen Mensual "&$C$3&"'!D"&11)) | V11: =IF(INDIRECT("'Resumen Mensual "&$C$3&"'!E"&11)="","",INDIRECT("'Resumen Mensual "&$C$3&"'!E"&11)) | W11: =IF(INDIRECT("'Resumen Mensual "&$C$3&"'!F"&11)="","",INDIRECT("'Resumen Mensual "&$C$3&"'!F"&11)) | X11: =IF(INDIRECT("'Resumen Mensual "&$C$3&"'!G"&11)="","",INDIRECT("'Resumen Mensual "&$C$3&"'!G"&11)) | Y11: =IF(INDIRECT("'Resumen Mensual "&$C$3&"'!H"&11)="","",INDIRECT("'Resumen Mensual "&$C$3&"'!H"&11)) | Z11: =IF(INDIRECT("'Resumen Mensual "&$C$3&"'!I"&11)="","",INDIRECT("'Resumen Mensual "&$C$3&"'!I"&11)) | AA11: =IF(INDIRECT("'Resumen Mensual "&$C$3&"'!J"&11)="","",INDIRECT("'Resumen Mensual "&$C$3&"'!J"&11)) | AB11: =IF(INDIRECT("'Resumen Mensual "&$C$3&"'!K"&11)="","",INDIRECT("'Resumen Mensual "&$C$3&"'!K"&11)) | AC11: =IF(INDIRECT("'Resumen Mensual "&$C$3&"'!L"&11)="","",INDIRECT("'Resumen Mensual "&$C$3&"'!L"&11)) | AD11: =IF(INDIRECT("'Resumen Mensual "&$C$3&"'!M"&11)="","",INDIRECT("'Resumen Mensual "&$C$3&"'!M"&11)) | AE11: =IF(INDIRECT("'Resumen Mensual "&$C$3&"'!N"&11)="","",INDIRECT("'Resumen Mensual "&$C$3&"'!N"&11)) | AF11: =IF(INDIRECT("'Resumen Mensual "&$C$3&"'!O"&11)="","",INDIRECT("'Resumen Mensual "&$C$3&"'!O"&11)) | AG11: =IF(INDIRECT("'Resumen Mensual "&$C$3&"'!P"&11)="","",INDIRECT("'Resumen Mensual "&$C$3&"'!P"&11)) | AH11: =IF(INDIRECT("'Resumen Mensual "&$C$3&"'!Q"&11)="","",INDIRECT("'Resumen Mensual "&$C$3&"'!Q"&11)) | AI11: =IF(INDIRECT("'Resumen Mensual "&$C$3&"'!R"&11)="","",INDIRECT("'Resumen Mensual "&$C$3&"'!R"&11))
R12: Octubre | S12: =IF(INDIRECT("'Resumen Mensual "&$C$3&"'!B"&12)="","",INDIRECT("'Resumen Mensual "&$C$3&"'!B"&12)) | T12: =IF(INDIRECT("'Resumen Mensual "&$C$3&"'!C"&12)="","",INDIRECT("'Resumen Mensual "&$C$3&"'!C"&12)) | U12: =IF(INDIRECT("'Resumen Mensual "&$C$3&"'!D"&12)="","",INDIRECT("'Resumen Mensual "&$C$3&"'!D"&12)) | V12: =IF(INDIRECT("'Resumen Mensual "&$C$3&"'!E"&12)="","",INDIRECT("'Resumen Mensual "&$C$3&"'!E"&12)) | W12: =IF(INDIRECT("'Resumen Mensual "&$C$3&"'!F"&12)="","",INDIRECT("'Resumen Mensual "&$C$3&"'!F"&12)) | X12: =IF(INDIRECT("'Resumen Mensual "&$C$3&"'!G"&12)="","",INDIRECT("'Resumen Mensual "&$C$3&"'!G"&12)) | Y12: =IF(INDIRECT("'Resumen Mensual "&$C$3&"'!H"&12)="","",INDIRECT("'Resumen Mensual "&$C$3&"'!H"&12)) | Z12: =IF(INDIRECT("'Resumen Mensual "&$C$3&"'!I"&12)="","",INDIRECT("'Resumen Mensual "&$C$3&"'!I"&12)) | AA12: =IF(INDIRECT("'Resumen Mensual "&$C$3&"'!J"&12)="","",INDIRECT("'Resumen Mensual "&$C$3&"'!J"&12)) | AB12: =IF(INDIRECT("'Resumen Mensual "&$C$3&"'!K"&12)="","",INDIRECT("'Resumen Mensual "&$C$3&"'!K"&12)) | AC12: =IF(INDIRECT("'Resumen Mensual "&$C$3&"'!L"&12)="","",INDIRECT("'Resumen Mensual "&$C$3&"'!L"&12)) | AD12: =IF(INDIRECT("'Resumen Mensual "&$C$3&"'!M"&12)="","",INDIRECT("'Resumen Mensual "&$C$3&"'!M"&12)) | AE12: =IF(INDIRECT("'Resumen Mensual "&$C$3&"'!N"&12)="","",INDIRECT("'Resumen Mensual "&$C$3&"'!N"&12)) | AF12: =IF(INDIRECT("'Resumen Mensual "&$C$3&"'!O"&12)="","",INDIRECT("'Resumen Mensual "&$C$3&"'!O"&12)) | AG12: =IF(INDIRECT("'Resumen Mensual "&$C$3&"'!P"&12)="","",INDIRECT("'Resumen Mensual "&$C$3&"'!P"&12)) | AH12: =IF(INDIRECT("'Resumen Mensual "&$C$3&"'!Q"&12)="","",INDIRECT("'Resumen Mensual "&$C$3&"'!Q"&12)) | AI12: =IF(INDIRECT("'Resumen Mensual "&$C$3&"'!R"&12)="","",INDIRECT("'Resumen Mensual "&$C$3&"'!R"&12))
R13: Noviembre | S13: =IF(INDIRECT("'Resumen Mensual "&$C$3&"'!B"&13)="","",INDIRECT("'Resumen Mensual "&$C$3&"'!B"&13)) | T13: =IF(INDIRECT("'Resumen Mensual "&$C$3&"'!C"&13)="","",INDIRECT("'Resumen Mensual "&$C$3&"'!C"&13)) | U13: =IF(INDIRECT("'Resumen Mensual "&$C$3&"'!D"&13)="","",INDIRECT("'Resumen Mensual "&$C$3&"'!D"&13)) | V13: =IF(INDIRECT("'Resumen Mensual "&$C$3&"'!E"&13)="","",INDIRECT("'Resumen Mensual "&$C$3&"'!E"&13)) | W13: =IF(INDIRECT("'Resumen Mensual "&$C$3&"'!F"&13)="","",INDIRECT("'Resumen Mensual "&$C$3&"'!F"&13)) | X13: =IF(INDIRECT("'Resumen Mensual "&$C$3&"'!G"&13)="","",INDIRECT("'Resumen Mensual "&$C$3&"'!G"&13)) | Y13: =IF(INDIRECT("'Resumen Mensual "&$C$3&"'!H"&13)="","",INDIRECT("'Resumen Mensual "&$C$3&"'!H"&13)) | Z13: =IF(INDIRECT("'Resumen Mensual "&$C$3&"'!I"&13)="","",INDIRECT("'Resumen Mensual "&$C$3&"'!I"&13)) | AA13: =IF(INDIRECT("'Resumen Mensual "&$C$3&"'!J"&13)="","",INDIRECT("'Resumen Mensual "&$C$3&"'!J"&13)) | AB13: =IF(INDIRECT("'Resumen Mensual "&$C$3&"'!K"&13)="","",INDIRECT("'Resumen Mensual "&$C$3&"'!K"&13)) | AC13: =IF(INDIRECT("'Resumen Mensual "&$C$3&"'!L"&13)="","",INDIRECT("'Resumen Mensual "&$C$3&"'!L"&13)) | AD13: =IF(INDIRECT("'Resumen Mensual "&$C$3&"'!M"&13)="","",INDIRECT("'Resumen Mensual "&$C$3&"'!M"&13)) | AE13: =IF(INDIRECT("'Resumen Mensual "&$C$3&"'!N"&13)="","",INDIRECT("'Resumen Mensual "&$C$3&"'!N"&13)) | AF13: =IF(INDIRECT("'Resumen Mensual "&$C$3&"'!O"&13)="","",INDIRECT("'Resumen Mensual "&$C$3&"'!O"&13)) | AG13: =IF(INDIRECT("'Resumen Mensual "&$C$3&"'!P"&13)="","",INDIRECT("'Resumen Mensual "&$C$3&"'!P"&13)) | AH13: =IF(INDIRECT("'Resumen Mensual "&$C$3&"'!Q"&13)="","",INDIRECT("'Resumen Mensual "&$C$3&"'!Q"&13)) | AI13: =IF(INDIRECT("'Resumen Mensual "&$C$3&"'!R"&13)="","",INDIRECT("'Resumen Mensual "&$C$3&"'!R"&13))
R14: Diciembre | S14: =IF(INDIRECT("'Resumen Mensual "&$C$3&"'!B"&14)="","",INDIRECT("'Resumen Mensual "&$C$3&"'!B"&14)) | T14: =IF(INDIRECT("'Resumen Mensual "&$C$3&"'!C"&14)="","",INDIRECT("'Resumen Mensual "&$C$3&"'!C"&14)) | U14: =IF(INDIRECT("'Resumen Mensual "&$C$3&"'!D"&14)="","",INDIRECT("'Resumen Mensual "&$C$3&"'!D"&14)) | V14: =IF(INDIRECT("'Resumen Mensual "&$C$3&"'!E"&14)="","",INDIRECT("'Resumen Mensual "&$C$3&"'!E"&14)) | W14: =IF(INDIRECT("'Resumen Mensual "&$C$3&"'!F"&14)="","",INDIRECT("'Resumen Mensual "&$C$3&"'!F"&14)) | X14: =IF(INDIRECT("'Resumen Mensual "&$C$3&"'!G"&14)="","",INDIRECT("'Resumen Mensual "&$C$3&"'!G"&14)) | Y14: =IF(INDIRECT("'Resumen Mensual "&$C$3&"'!H"&14)="","",INDIRECT("'Resumen Mensual "&$C$3&"'!H"&14)) | Z14: =IF(INDIRECT("'Resumen Mensual "&$C$3&"'!I"&14)="","",INDIRECT("'Resumen Mensual "&$C$3&"'!I"&14)) | AA14: =IF(INDIRECT("'Resumen Mensual "&$C$3&"'!J"&14)="","",INDIRECT("'Resumen Mensual "&$C$3&"'!J"&14)) | AB14: =IF(INDIRECT("'Resumen Mensual "&$C$3&"'!K"&14)="","",INDIRECT("'Resumen Mensual "&$C$3&"'!K"&14)) | AC14: =IF(INDIRECT("'Resumen Mensual "&$C$3&"'!L"&14)="","",INDIRECT("'Resumen Mensual "&$C$3&"'!L"&14)) | AD14: =IF(INDIRECT("'Resumen Mensual "&$C$3&"'!M"&14)="","",INDIRECT("'Resumen Mensual "&$C$3&"'!M"&14)) | AE14: =IF(INDIRECT("'Resumen Mensual "&$C$3&"'!N"&14)="","",INDIRECT("'Resumen Mensual "&$C$3&"'!N"&14)) | AF14: =IF(INDIRECT("'Resumen Mensual "&$C$3&"'!O"&14)="","",INDIRECT("'Resumen Mensual "&$C$3&"'!O"&14)) | AG14: =IF(INDIRECT("'Resumen Mensual "&$C$3&"'!P"&14)="","",INDIRECT("'Resumen Mensual "&$C$3&"'!P"&14)) | AH14: =IF(INDIRECT("'Resumen Mensual "&$C$3&"'!Q"&14)="","",INDIRECT("'Resumen Mensual "&$C$3&"'!Q"&14)) | AI14: =IF(INDIRECT("'Resumen Mensual "&$C$3&"'!R"&14)="","",INDIRECT("'Resumen Mensual "&$C$3&"'!R"&14))
R15: Total | S15: =INDIRECT("'Resumen Mensual "&$C$3&"'!B15") | T15: =INDIRECT("'Resumen Mensual "&$C$3&"'!C15") | U15: =INDIRECT("'Resumen Mensual "&$C$3&"'!D15") | V15: =INDIRECT("'Resumen Mensual "&$C$3&"'!E15") | W15: =INDIRECT("'Resumen Mensual "&$C$3&"'!F15") | X15: =INDIRECT("'Resumen Mensual "&$C$3&"'!G15") | Y15: =INDIRECT("'Resumen Mensual "&$C$3&"'!H15") | Z15: =INDIRECT("'Resumen Mensual "&$C$3&"'!I15") | AA15: =INDIRECT("'Resumen Mensual "&$C$3&"'!J15") | AB15: =INDIRECT("'Resumen Mensual "&$C$3&"'!K15") | AC15: =INDIRECT("'Resumen Mensual "&$C$3&"'!L15") | AD15: =INDIRECT("'Resumen Mensual "&$C$3&"'!M15") | AE15: =INDIRECT("'Resumen Mensual "&$C$3&"'!N15") | AF15: =INDIRECT("'Resumen Mensual "&$C$3&"'!O15") | AG15: =INDIRECT("'Resumen Mensual "&$C$3&"'!P15") | AH15: =INDIRECT("'Resumen Mensual "&$C$3&"'!Q15") | AI15: =INDIRECT("'Resumen Mensual "&$C$3&"'!R15")

Sheet Resumen Mensual 2026
A1: MATRIZ DE RESUMEN MENSUAL Y ANÁLISIS DE GASTOS 2026
A2: Mes | B2: Ingresos (€) | C2: Gastos (€) | D2: Ahorro Neto (€) | E2: Tasa de Ahorro (%) | F2: Vivienda | G2: Comida y bebida | H2: Ocio / Viajes | I2: Ocio / salidas | J2: Tecnología / Otros | K2: Transporte / Gasolina | L2: Ocio / Eventos | M2: Salud | N2: Educación | O2: Ropa | P2: Suscripciones | Q2: Mascotas | R2: Otros
A3: Enero | B3: =IF(COUNTIFS('Gastos e Ingresos 2026'!$A:$A, ">="&DATE(2026, 1, 1), 'Gastos e Ingresos 2026'!$A:$A, "<"&DATE(2026, 2, 1))>0, SUMIFS('Gastos e Ingresos 2026'!$E:$E, 'Gastos e Ingresos 2026'!$D:$D, "Ingreso", 'Gastos e Ingresos 2026'!$A:$A, ">="&DATE(2026, 1, 1), 'Gastos e Ingresos 2026'!$A:$A, "<"&DATE(2026, 2, 1)), "") | C3: =IF(COUNTIFS('Gastos e Ingresos 2026'!$A:$A, ">="&DATE(2026, 1, 1), 'Gastos e Ingresos 2026'!$A:$A, "<"&DATE(2026, 2, 1))>0, SUMIFS('Gastos e Ingresos 2026'!$E:$E, 'Gastos e Ingresos 2026'!$D:$D, "Gasto", 'Gastos e Ingresos 2026'!$A:$A, ">="&DATE(2026, 1, 1), 'Gastos e Ingresos 2026'!$A:$A, "<"&DATE(2026, 2, 1)), "") | D3: =IF(B3="","",B3-C3) | E3: =IF(B3="","",IF(B3>0, D3/B3, 0)) | F3: =IF(COUNTIFS('Gastos e Ingresos 2026'!$A:$A, ">="&DATE(2026, 1, 1), 'Gastos e Ingresos 2026'!$A:$A, "<"&DATE(2026, 2, 1))>0, SUMIFS('Gastos e Ingresos 2026'!$E:$E, 'Gastos e Ingresos 2026'!$D:$D, "Gasto", 'Gastos e Ingresos 2026'!$C:$C, F$2, 'Gastos e Ingresos 2026'!$A:$A, ">="&DATE(2026, 1, 1), 'Gastos e Ingresos 2026'!$A:$A, "<"&DATE(2026, 2, 1)), "") | G3: =IF(COUNTIFS('Gastos e Ingresos 2026'!$A:$A, ">="&DATE(2026, 1, 1), 'Gastos e Ingresos 2026'!$A:$A, "<"&DATE(2026, 2, 1))>0, SUMIFS('Gastos e Ingresos 2026'!$E:$E, 'Gastos e Ingresos 2026'!$D:$D, "Gasto", 'Gastos e Ingresos 2026'!$C:$C, G$2, 'Gastos e Ingresos 2026'!$A:$A, ">="&DATE(2026, 1, 1), 'Gastos e Ingresos 2026'!$A:$A, "<"&DATE(2026, 2, 1)), "") | H3: =IF(COUNTIFS('Gastos e Ingresos 2026'!$A:$A, ">="&DATE(2026, 1, 1), 'Gastos e Ingresos 2026'!$A:$A, "<"&DATE(2026, 2, 1))>0, SUMIFS('Gastos e Ingresos 2026'!$E:$E, 'Gastos e Ingresos 2026'!$D:$D, "Gasto", 'Gastos e Ingresos 2026'!$C:$C, H$2, 'Gastos e Ingresos 2026'!$A:$A, ">="&DATE(2026, 1, 1), 'Gastos e Ingresos 2026'!$A:$A, "<"&DATE(2026, 2, 1)), "") | I3: =IF(COUNTIFS('Gastos e Ingresos 2026'!$A:$A, ">="&DATE(2026, 1, 1), 'Gastos e Ingresos 2026'!$A:$A, "<"&DATE(2026, 2, 1))>0, SUMIFS('Gastos e Ingresos 2026'!$E:$E, 'Gastos e Ingresos 2026'!$D:$D, "Gasto", 'Gastos e Ingresos 2026'!$C:$C, I$2, 'Gastos e Ingresos 2026'!$A:$A, ">="&DATE(2026, 1, 1), 'Gastos e Ingresos 2026'!$A:$A, "<"&DATE(2026, 2, 1)), "") | J3: =IF(COUNTIFS('Gastos e Ingresos 2026'!$A:$A, ">="&DATE(2026, 1, 1), 'Gastos e Ingresos 2026'!$A:$A, "<"&DATE(2026, 2, 1))>0, SUMIFS('Gastos e Ingresos 2026'!$E:$E, 'Gastos e Ingresos 2026'!$D:$D, "Gasto", 'Gastos e Ingresos 2026'!$C:$C, J$2, 'Gastos e Ingresos 2026'!$A:$A, ">="&DATE(2026, 1, 1), 'Gastos e Ingresos 2026'!$A:$A, "<"&DATE(2026, 2, 1)), "") | K3: =IF(COUNTIFS('Gastos e Ingresos 2026'!$A:$A, ">="&DATE(2026, 1, 1), 'Gastos e Ingresos 2026'!$A:$A, "<"&DATE(2026, 2, 1))>0, SUMIFS('Gastos e Ingresos 2026'!$E:$E, 'Gastos e Ingresos 2026'!$D:$D, "Gasto", 'Gastos e Ingresos 2026'!$C:$C, K$2, 'Gastos e Ingresos 2026'!$A:$A, ">="&DATE(2026, 1, 1), 'Gastos e Ingresos 2026'!$A:$A, "<"&DATE(2026, 2, 1)), "") | L3: =IF(COUNTIFS('Gastos e Ingresos 2026'!$A:$A, ">="&DATE(2026, 1, 1), 'Gastos e Ingresos 2026'!$A:$A, "<"&DATE(2026, 2, 1))>0, SUMIFS('Gastos e Ingresos 2026'!$E:$E, 'Gastos e Ingresos 2026'!$D:$D, "Gasto", 'Gastos e Ingresos 2026'!$C:$C, L$2, 'Gastos e Ingresos 2026'!$A:$A, ">="&DATE(2026, 1, 1), 'Gastos e Ingresos 2026'!$A:$A, "<"&DATE(2026, 2, 1)), "") | M3: =IF(COUNTIFS('Gastos e Ingresos 2026'!$A:$A, ">="&DATE(2026, 1, 1), 'Gastos e Ingresos 2026'!$A:$A, "<"&DATE(2026, 2, 1))>0, SUMIFS('Gastos e Ingresos 2026'!$E:$E, 'Gastos e Ingresos 2026'!$D:$D, "Gasto", 'Gastos e Ingresos 2026'!$C:$C, M$2, 'Gastos e Ingresos 2026'!$A:$A, ">="&DATE(2026, 1, 1), 'Gastos e Ingresos 2026'!$A:$A, "<"&DATE(2026, 2, 1)), "") | ... R3: =IF(COUNTIFS('Gastos e Ingresos 2026'!$A:$A, ">="&DATE(2026, 1, 1), 'Gastos e Ingresos 2026'!$A:$A, "<"&DATE(2026, 2, 1))>0, SUMIFS('Gastos e Ingresos 2026'!$E:$E, 'Gastos e Ingresos 2026'!$D:$D, "Gasto", 'Gastos e Ingresos 2026'!$C:$C, R$2, 'Gastos e Ingresos 2026'!$A:$A, ">="&DATE(2026, 1, 1), 'Gastos e Ingresos 2026'!$A:$A, "<"&DATE(2026, 2, 1)), "")
A4: Febrero | B4: =IF(COUNTIFS('Gastos e Ingresos 2026'!$A:$A, ">="&DATE(2026, 2, 1), 'Gastos e Ingresos 2026'!$A:$A, "<"&DATE(2026, 3, 1))>0, SUMIFS('Gastos e Ingresos 2026'!$E:$E, 'Gastos e Ingresos 2026'!$D:$D, "Ingreso", 'Gastos e Ingresos 2026'!$A:$A, ">="&DATE(2026, 2, 1), 'Gastos e Ingresos 2026'!$A:$A, "<"&DATE(2026, 3, 1)), "") | C4: =IF(COUNTIFS('Gastos e Ingresos 2026'!$A:$A, ">="&DATE(2026, 2, 1), 'Gastos e Ingresos 2026'!$A:$A, "<"&DATE(2026, 3, 1))>0, SUMIFS('Gastos e Ingresos 2026'!$E:$E, 'Gastos e Ingresos 2026'!$D:$D, "Gasto", 'Gastos e Ingresos 2026'!$A:$A, ">="&DATE(2026, 2, 1), 'Gastos e Ingresos 2026'!$A:$A, "<"&DATE(2026, 3, 1)), "") | D4: =IF(B4="","",B4-C4) | E4: =IF(B4="","",IF(B4>0, D4/B4, 0)) | F4: =IF(COUNTIFS('Gastos e Ingresos 2026'!$A:$A, ">="&DATE(2026, 2, 1), 'Gastos e Ingresos 2026'!$A:$A, "<"&DATE(2026, 3, 1))>0, SUMIFS('Gastos e Ingresos 2026'!$E:$E, 'Gastos e Ingresos 2026'!$D:$D, "Gasto", 'Gastos e Ingresos 2026'!$C:$C, F$2, 'Gastos e Ingresos 2026'!$A:$A, ">="&DATE(2026, 2, 1), 'Gastos e Ingresos 2026'!$A:$A, "<"&DATE(2026, 3, 1)), "") | G4: =IF(COUNTIFS('Gastos e Ingresos 2026'!$A:$A, ">="&DATE(2026, 2, 1), 'Gastos e Ingresos 2026'!$A:$A, "<"&DATE(2026, 3, 1))>0, SUMIFS('Gastos e Ingresos 2026'!$E:$E, 'Gastos e Ingresos 2026'!$D:$D, "Gasto", 'Gastos e Ingresos 2026'!$C:$C, G$2, 'Gastos e Ingresos 2026'!$A:$A, ">="&DATE(2026, 2, 1), 'Gastos e Ingresos 2026'!$A:$A, "<"&DATE(2026, 3, 1)), "") | H4: =IF(COUNTIFS('Gastos e Ingresos 2026'!$A:$A, ">="&DATE(2026, 2, 1), 'Gastos e Ingresos 2026'!$A:$A, "<"&DATE(2026, 3, 1))>0, SUMIFS('Gastos e Ingresos 2026'!$E:$E, 'Gastos e Ingresos 2026'!$D:$D, "Gasto", 'Gastos e Ingresos 2026'!$C:$C, H$2, 'Gastos e Ingresos 2026'!$A:$A, ">="&DATE(2026, 2, 1), 'Gastos e Ingresos 2026'!$A:$A, "<"&DATE(2026, 3, 1)), "") | I4: =IF(COUNTIFS('Gastos e Ingresos 2026'!$A:$A, ">="&DATE(2026, 2, 1), 'Gastos e Ingresos 2026'!$A:$A, "<"&DATE(2026, 3, 1))>0, SUMIFS('Gastos e Ingresos 2026'!$E:$E, 'Gastos e Ingresos 2026'!$D:$D, "Gasto", 'Gastos e Ingresos 2026'!$C:$C, I$2, 'Gastos e Ingresos 2026'!$A:$A, ">="&DATE(2026, 2, 1), 'Gastos e Ingresos 2026'!$A:$A, "<"&DATE(2026, 3, 1)), "") | J4: =IF(COUNTIFS('Gastos e Ingresos 2026'!$A:$A, ">="&DATE(2026, 2, 1), 'Gastos e Ingresos 2026'!$A:$A, "<"&DATE(2026, 3, 1))>0, SUMIFS('Gastos e Ingresos 2026'!$E:$E, 'Gastos e Ingresos 2026'!$D:$D, "Gasto", 'Gastos e Ingresos 2026'!$C:$C, J$2, 'Gastos e Ingresos 2026'!$A:$A, ">="&DATE(2026, 2, 1), 'Gastos e Ingresos 2026'!$A:$A, "<"&DATE(2026, 3, 1)), "") | K4: =IF(COUNTIFS('Gastos e Ingresos 2026'!$A:$A, ">="&DATE(2026, 2, 1), 'Gastos e Ingresos 2026'!$A:$A, "<"&DATE(2026, 3, 1))>0, SUMIFS('Gastos e Ingresos 2026'!$E:$E, 'Gastos e Ingresos 2026'!$D:$D, "Gasto", 'Gastos e Ingresos 2026'!$C:$C, K$2, 'Gastos e Ingresos 2026'!$A:$A, ">="&DATE(2026, 2, 1), 'Gastos e Ingresos 2026'!$A:$A, "<"&DATE(2026, 3, 1)), "") | L4: =IF(COUNTIFS('Gastos e Ingresos 2026'!$A:$A, ">="&DATE(2026, 2, 1), 'Gastos e Ingresos 2026'!$A:$A, "<"&DATE(2026, 3, 1))>0, SUMIFS('Gastos e Ingresos 2026'!$E:$E, 'Gastos e Ingresos 2026'!$D:$D, "Gasto", 'Gastos e Ingresos 2026'!$C:$C, L$2, 'Gastos e Ingresos 2026'!$A:$A, ">="&DATE(2026, 2, 1), 'Gastos e Ingresos 2026'!$A:$A, "<"&DATE(2026, 3, 1)), "") | M4: =IF(COUNTIFS('Gastos e Ingresos 2026'!$A:$A, ">="&DATE(2026, 2, 1), 'Gastos e Ingresos 2026'!$A:$A, "<"&DATE(2026, 3, 1))>0, SUMIFS('Gastos e Ingresos 2026'!$E:$E, 'Gastos e Ingresos 2026'!$D:$D, "Gasto", 'Gastos e Ingresos 2026'!$C:$C, M$2, 'Gastos e Ingresos 2026'!$A:$A, ">="&DATE(2026, 2, 1), 'Gastos e Ingresos 2026'!$A:$A, "<"&DATE(2026, 3, 1)), "") | ... R4: =IF(COUNTIFS('Gastos e Ingresos 2026'!$A:$A, ">="&DATE(2026, 2, 1), 'Gastos e Ingresos 2026'!$A:$A, "<"&DATE(2026, 3, 1))>0, SUMIFS('Gastos e Ingresos 2026'!$E:$E, 'Gastos e Ingresos 2026'!$D:$D, "Gasto", 'Gastos e Ingresos 2026'!$C:$C, R$2, 'Gastos e Ingresos 2026'!$A:$A, ">="&DATE(2026, 2, 1), 'Gastos e Ingresos 2026'!$A:$A, "<"&DATE(2026, 3, 1)), "")
A5: Marzo | B5: =IF(COUNTIFS('Gastos e Ingresos 2026'!$A:$A, ">="&DATE(2026, 3, 1), 'Gastos e Ingresos 2026'!$A:$A, "<"&DATE(2026, 4, 1))>0, SUMIFS('Gastos e Ingresos 2026'!$E:$E, 'Gastos e Ingresos 2026'!$D:$D, "Ingreso", 'Gastos e Ingresos 2026'!$A:$A, ">="&DATE(2026, 3, 1), 'Gastos e Ingresos 2026'!$A:$A, "<"&DATE(2026, 4, 1)), "") | C5: =IF(COUNTIFS('Gastos e Ingresos 2026'!$A:$A, ">="&DATE(2026, 3, 1), 'Gastos e Ingresos 2026'!$A:$A, "<"&DATE(2026, 4, 1))>0, SUMIFS('Gastos e Ingresos 2026'!$E:$E, 'Gastos e Ingresos 2026'!$D:$D, "Gasto", 'Gastos e Ingresos 2026'!$A:$A, ">="&DATE(2026, 3, 1), 'Gastos e Ingresos 2026'!$A:$A, "<"&DATE(2026, 4, 1)), "") | D5: =IF(B5="","",B5-C5) | E5: =IF(B5="","",IF(B5>0, D5/B5, 0)) | F5: =IF(COUNTIFS('Gastos e Ingresos 2026'!$A:$A, ">="&DATE(2026, 3, 1), 'Gastos e Ingresos 2026'!$A:$A, "<"&DATE(2026, 4, 1))>0, SUMIFS('Gastos e Ingresos 2026'!$E:$E, 'Gastos e Ingresos 2026'!$D:$D, "Gasto", 'Gastos e Ingresos 2026'!$C:$C, F$2, 'Gastos e Ingresos 2026'!$A:$A, ">="&DATE(2026, 3, 1), 'Gastos e Ingresos 2026'!$A:$A, "<"&DATE(2026, 4, 1)), "") | G5: =IF(COUNTIFS('Gastos e Ingresos 2026'!$A:$A, ">="&DATE(2026, 3, 1), 'Gastos e Ingresos 2026'!$A:$A, "<"&DATE(2026, 4, 1))>0, SUMIFS('Gastos e Ingresos 2026'!$E:$E, 'Gastos e Ingresos 2026'!$D:$D, "Gasto", 'Gastos e Ingresos 2026'!$C:$C, G$2, 'Gastos e Ingresos 2026'!$A:$A, ">="&DATE(2026, 3, 1), 'Gastos e Ingresos 2026'!$A:$A, "<"&DATE(2026, 4, 1)), "") | H5: =IF(COUNTIFS('Gastos e Ingresos 2026'!$A:$A, ">="&DATE(2026, 3, 1), 'Gastos e Ingresos 2026'!$A:$A, "<"&DATE(2026, 4, 1))>0, SUMIFS('Gastos e Ingresos 2026'!$E:$E, 'Gastos e Ingresos 2026'!$D:$D, "Gasto", 'Gastos e Ingresos 2026'!$C:$C, H$2, 'Gastos e Ingresos 2026'!$A:$A, ">="&DATE(2026, 3, 1), 'Gastos e Ingresos 2026'!$A:$A, "<"&DATE(2026, 4, 1)), "") | I5: =IF(COUNTIFS('Gastos e Ingresos 2026'!$A:$A, ">="&DATE(2026, 3, 1), 'Gastos e Ingresos 2026'!$A:$A, "<"&DATE(2026, 4, 1))>0, SUMIFS('Gastos e Ingresos 2026'!$E:$E, 'Gastos e Ingresos 2026'!$D:$D, "Gasto", 'Gastos e Ingresos 2026'!$C:$C, I$2, 'Gastos e Ingresos 2026'!$A:$A, ">="&DATE(2026, 3, 1), 'Gastos e Ingresos 2026'!$A:$A, "<"&DATE(2026, 4, 1)), "") | J5: =IF(COUNTIFS('Gastos e Ingresos 2026'!$A:$A, ">="&DATE(2026, 3, 1), 'Gastos e Ingresos 2026'!$A:$A, "<"&DATE(2026, 4, 1))>0, SUMIFS('Gastos e Ingresos 2026'!$E:$E, 'Gastos e Ingresos 2026'!$D:$D, "Gasto", 'Gastos e Ingresos 2026'!$C:$C, J$2, 'Gastos e Ingresos 2026'!$A:$A, ">="&DATE(2026, 3, 1), 'Gastos e Ingresos 2026'!$A:$A, "<"&DATE(2026, 4, 1)), "") | K5: =IF(COUNTIFS('Gastos e Ingresos 2026'!$A:$A, ">="&DATE(2026, 3, 1), 'Gastos e Ingresos 2026'!$A:$A, "<"&DATE(2026, 4, 1))>0, SUMIFS('Gastos e Ingresos 2026'!$E:$E, 'Gastos e Ingresos 2026'!$D:$D, "Gasto", 'Gastos e Ingresos 2026'!$C:$C, K$2, 'Gastos e Ingresos 2026'!$A:$A, ">="&DATE(2026, 3, 1), 'Gastos e Ingresos 2026'!$A:$A, "<"&DATE(2026, 4, 1)), "") | L5: =IF(COUNTIFS('Gastos e Ingresos 2026'!$A:$A, ">="&DATE(2026, 3, 1), 'Gastos e Ingresos 2026'!$A:$A, "<"&DATE(2026, 4, 1))>0, SUMIFS('Gastos e Ingresos 2026'!$E:$E, 'Gastos e Ingresos 2026'!$D:$D, "Gasto", 'Gastos e Ingresos 2026'!$C:$C, L$2, 'Gastos e Ingresos 2026'!$A:$A, ">="&DATE(2026, 3, 1), 'Gastos e Ingresos 2026'!$A:$A, "<"&DATE(2026, 4, 1)), "") | M5: =IF(COUNTIFS('Gastos e Ingresos 2026'!$A:$A, ">="&DATE(2026, 3, 1), 'Gastos e Ingresos 2026'!$A:$A, "<"&DATE(2026, 4, 1))>0, SUMIFS('Gastos e Ingresos 2026'!$E:$E, 'Gastos e Ingresos 2026'!$D:$D, "Gasto", 'Gastos e Ingresos 2026'!$C:$C, M$2, 'Gastos e Ingresos 2026'!$A:$A, ">="&DATE(2026, 3, 1), 'Gastos e Ingresos 2026'!$A:$A, "<"&DATE(2026, 4, 1)), "") | ... R5: =IF(COUNTIFS('Gastos e Ingresos 2026'!$A:$A, ">="&DATE(2026, 3, 1), 'Gastos e Ingresos 2026'!$A:$A, "<"&DATE(2026, 4, 1))>0, SUMIFS('Gastos e Ingresos 2026'!$E:$E, 'Gastos e Ingresos 2026'!$D:$D, "Gasto", 'Gastos e Ingresos 2026'!$C:$C, R$2, 'Gastos e Ingresos 2026'!$A:$A, ">="&DATE(2026, 3, 1), 'Gastos e Ingresos 2026'!$A:$A, "<"&DATE(2026, 4, 1)), "")
A6: Abril | B6: =IF(COUNTIFS('Gastos e Ingresos 2026'!$A:$A, ">="&DATE(2026, 4, 1), 'Gastos e Ingresos 2026'!$A:$A, "<"&DATE(2026, 5, 1))>0, SUMIFS('Gastos e Ingresos 2026'!$E:$E, 'Gastos e Ingresos 2026'!$D:$D, "Ingreso", 'Gastos e Ingresos 2026'!$A:$A, ">="&DATE(2026, 4, 1), 'Gastos e Ingresos 2026'!$A:$A, "<"&DATE(2026, 5, 1)), "") | C6: =IF(COUNTIFS('Gastos e Ingresos 2026'!$A:$A, ">="&DATE(2026, 4, 1), 'Gastos e Ingresos 2026'!$A:$A, "<"&DATE(2026, 5, 1))>0, SUMIFS('Gastos e Ingresos 2026'!$E:$E, 'Gastos e Ingresos 2026'!$D:$D, "Gasto", 'Gastos e Ingresos 2026'!$A:$A, ">="&DATE(2026, 4, 1), 'Gastos e Ingresos 2026'!$A:$A, "<"&DATE(2026, 5, 1)), "") | D6: =IF(B6="","",B6-C6) | E6: =IF(B6="","",IF(B6>0, D6/B6, 0)) | F6: =IF(COUNTIFS('Gastos e Ingresos 2026'!$A:$A, ">="&DATE(2026, 4, 1), 'Gastos e Ingresos 2026'!$A:$A, "<"&DATE(2026, 5, 1))>0, SUMIFS('Gastos e Ingresos 2026'!$E:$E, 'Gastos e Ingresos 2026'!$D:$D, "Gasto", 'Gastos e Ingresos 2026'!$C:$C, F$2, 'Gastos e Ingresos 2026'!$A:$A, ">="&DATE(2026, 4, 1), 'Gastos e Ingresos 2026'!$A:$A, "<"&DATE(2026, 5, 1)), "") | G6: =IF(COUNTIFS('Gastos e Ingresos 2026'!$A:$A, ">="&DATE(2026, 4, 1), 'Gastos e Ingresos 2026'!$A:$A, "<"&DATE(2026, 5, 1))>0, SUMIFS('Gastos e Ingresos 2026'!$E:$E, 'Gastos e Ingresos 2026'!$D:$D, "Gasto", 'Gastos e Ingresos 2026'!$C:$C, G$2, 'Gastos e Ingresos 2026'!$A:$A, ">="&DATE(2026, 4, 1), 'Gastos e Ingresos 2026'!$A:$A, "<"&DATE(2026, 5, 1)), "") | H6: =IF(COUNTIFS('Gastos e Ingresos 2026'!$A:$A, ">="&DATE(2026, 4, 1), 'Gastos e Ingresos 2026'!$A:$A, "<"&DATE(2026, 5, 1))>0, SUMIFS('Gastos e Ingresos 2026'!$E:$E, 'Gastos e Ingresos 2026'!$D:$D, "Gasto", 'Gastos e Ingresos 2026'!$C:$C, H$2, 'Gastos e Ingresos 2026'!$A:$A, ">="&DATE(2026, 4, 1), 'Gastos e Ingresos 2026'!$A:$A, "<"&DATE(2026, 5, 1)), "") | I6: =IF(COUNTIFS('Gastos e Ingresos 2026'!$A:$A, ">="&DATE(2026, 4, 1), 'Gastos e Ingresos 2026'!$A:$A, "<"&DATE(2026, 5, 1))>0, SUMIFS('Gastos e Ingresos 2026'!$E:$E, 'Gastos e Ingresos 2026'!$D:$D, "Gasto", 'Gastos e Ingresos 2026'!$C:$C, I$2, 'Gastos e Ingresos 2026'!$A:$A, ">="&DATE(2026, 4, 1), 'Gastos e Ingresos 2026'!$A:$A, "<"&DATE(2026, 5, 1)), "") | J6: =IF(COUNTIFS('Gastos e Ingresos 2026'!$A:$A, ">="&DATE(2026, 4, 1), 'Gastos e Ingresos 2026'!$A:$A, "<"&DATE(2026, 5, 1))>0, SUMIFS('Gastos e Ingresos 2026'!$E:$E, 'Gastos e Ingresos 2026'!$D:$D, "Gasto", 'Gastos e Ingresos 2026'!$C:$C, J$2, 'Gastos e Ingresos 2026'!$A:$A, ">="&DATE(2026, 4, 1), 'Gastos e Ingresos 2026'!$A:$A, "<"&DATE(2026, 5, 1)), "") | K6: =IF(COUNTIFS('Gastos e Ingresos 2026'!$A:$A, ">="&DATE(2026, 4, 1), 'Gastos e Ingresos 2026'!$A:$A, "<"&DATE(2026, 5, 1))>0, SUMIFS('Gastos e Ingresos 2026'!$E:$E, 'Gastos e Ingresos 2026'!$D:$D, "Gasto", 'Gastos e Ingresos 2026'!$C:$C, K$2, 'Gastos e Ingresos 2026'!$A:$A, ">="&DATE(2026, 4, 1), 'Gastos e Ingresos 2026'!$A:$A, "<"&DATE(2026, 5, 1)), "") | L6: =IF(COUNTIFS('Gastos e Ingresos 2026'!$A:$A, ">="&DATE(2026, 4, 1), 'Gastos e Ingresos 2026'!$A:$A, "<"&DATE(2026, 5, 1))>0, SUMIFS('Gastos e Ingresos 2026'!$E:$E, 'Gastos e Ingresos 2026'!$D:$D, "Gasto", 'Gastos e Ingresos 2026'!$C:$C, L$2, 'Gastos e Ingresos 2026'!$A:$A, ">="&DATE(2026, 4, 1), 'Gastos e Ingresos 2026'!$A:$A, "<"&DATE(2026, 5, 1)), "") | M6: =IF(COUNTIFS('Gastos e Ingresos 2026'!$A:$A, ">="&DATE(2026, 4, 1), 'Gastos e Ingresos 2026'!$A:$A, "<"&DATE(2026, 5, 1))>0, SUMIFS('Gastos e Ingresos 2026'!$E:$E, 'Gastos e Ingresos 2026'!$D:$D, "Gasto", 'Gastos e Ingresos 2026'!$C:$C, M$2, 'Gastos e Ingresos 2026'!$A:$A, ">="&DATE(2026, 4, 1), 'Gastos e Ingresos 2026'!$A:$A, "<"&DATE(2026, 5, 1)), "") | ... R6: =IF(COUNTIFS('Gastos e Ingresos 2026'!$A:$A, ">="&DATE(2026, 4, 1), 'Gastos e Ingresos 2026'!$A:$A, "<"&DATE(2026, 5, 1))>0, SUMIFS('Gastos e Ingresos 2026'!$E:$E, 'Gastos e Ingresos 2026'!$D:$D, "Gasto", 'Gastos e Ingresos 2026'!$C:$C, R$2, 'Gastos e Ingresos 2026'!$A:$A, ">="&DATE(2026, 4, 1), 'Gastos e Ingresos 2026'!$A:$A, "<"&DATE(2026, 5, 1)), "")
A7: Mayo | B7: =IF(COUNTIFS('Gastos e Ingresos 2026'!$A:$A, ">="&DATE(2026, 5, 1), 'Gastos e Ingresos 2026'!$A:$A, "<"&DATE(2026, 6, 1))>0, SUMIFS('Gastos e Ingresos 2026'!$E:$E, 'Gastos e Ingresos 2026'!$D:$D, "Ingreso", 'Gastos e Ingresos 2026'!$A:$A, ">="&DATE(2026, 5, 1), 'Gastos e Ingresos 2026'!$A:$A, "<"&DATE(2026, 6, 1)), "") | C7: =IF(COUNTIFS('Gastos e Ingresos 2026'!$A:$A, ">="&DATE(2026, 5, 1), 'Gastos e Ingresos 2026'!$A:$A, "<"&DATE(2026, 6, 1))>0, SUMIFS('Gastos e Ingresos 2026'!$E:$E, 'Gastos e Ingresos 2026'!$D:$D, "Gasto", 'Gastos e Ingresos 2026'!$A:$A, ">="&DATE(2026, 5, 1), 'Gastos e Ingresos 2026'!$A:$A, "<"&DATE(2026, 6, 1)), "") | D7: =IF(B7="","",B7-C7) | E7: =IF(B7="","",IF(B7>0, D7/B7, 0)) | F7: =IF(COUNTIFS('Gastos e Ingresos 2026'!$A:$A, ">="&DATE(2026, 5, 1), 'Gastos e Ingresos 2026'!$A:$A, "<"&DATE(2026, 6, 1))>0, SUMIFS('Gastos e Ingresos 2026'!$E:$E, 'Gastos e Ingresos 2026'!$D:$D, "Gasto", 'Gastos e Ingresos 2026'!$C:$C, F$2, 'Gastos e Ingresos 2026'!$A:$A, ">="&DATE(2026, 5, 1), 'Gastos e Ingresos 2026'!$A:$A, "<"&DATE(2026, 6, 1)), "") | G7: =IF(COUNTIFS('Gastos e Ingresos 2026'!$A:$A, ">="&DATE(2026, 5, 1), 'Gastos e Ingresos 2026'!$A:$A, "<"&DATE(2026, 6, 1))>0, SUMIFS('Gastos e Ingresos 2026'!$E:$E, 'Gastos e Ingresos 2026'!$D:$D, "Gasto", 'Gastos e Ingresos 2026'!$C:$C, G$2, 'Gastos e Ingresos 2026'!$A:$A, ">="&DATE(2026, 5, 1), 'Gastos e Ingresos 2026'!$A:$A, "<"&DATE(2026, 6, 1)), "") | H7: =IF(COUNTIFS('Gastos e Ingresos 2026'!$A:$A, ">="&DATE(2026, 5, 1), 'Gastos e Ingresos 2026'!$A:$A, "<"&DATE(2026, 6, 1))>0, SUMIFS('Gastos e Ingresos 2026'!$E:$E, 'Gastos e Ingresos 2026'!$D:$D, "Gasto", 'Gastos e Ingresos 2026'!$C:$C, H$2, 'Gastos e Ingresos 2026'!$A:$A, ">="&DATE(2026, 5, 1), 'Gastos e Ingresos 2026'!$A:$A, "<"&DATE(2026, 6, 1)), "") | I7: =IF(COUNTIFS('Gastos e Ingresos 2026'!$A:$A, ">="&DATE(2026, 5, 1), 'Gastos e Ingresos 2026'!$A:$A, "<"&DATE(2026, 6, 1))>0, SUMIFS('Gastos e Ingresos 2026'!$E:$E, 'Gastos e Ingresos 2026'!$D:$D, "Gasto", 'Gastos e Ingresos 2026'!$C:$C, I$2, 'Gastos e Ingresos 2026'!$A:$A, ">="&DATE(2026, 5, 1), 'Gastos e Ingresos 2026'!$A:$A, "<"&DATE(2026, 6, 1)), "") | J7: =IF(COUNTIFS('Gastos e Ingresos 2026'!$A:$A, ">="&DATE(2026, 5, 1), 'Gastos e Ingresos 2026'!$A:$A, "<"&DATE(2026, 6, 1))>0, SUMIFS('Gastos e Ingresos 2026'!$E:$E, 'Gastos e Ingresos 2026'!$D:$D, "Gasto", 'Gastos e Ingresos 2026'!$C:$C, J$2, 'Gastos e Ingresos 2026'!$A:$A, ">="&DATE(2026, 5, 1), 'Gastos e Ingresos 2026'!$A:$A, "<"&DATE(2026, 6, 1)), "") | K7: =IF(COUNTIFS('Gastos e Ingresos 2026'!$A:$A, ">="&DATE(2026, 5, 1), 'Gastos e Ingresos 2026'!$A:$A, "<"&DATE(2026, 6, 1))>0, SUMIFS('Gastos e Ingresos 2026'!$E:$E, 'Gastos e Ingresos 2026'!$D:$D, "Gasto", 'Gastos e Ingresos 2026'!$C:$C, K$2, 'Gastos e Ingresos 2026'!$A:$A, ">="&DATE(2026, 5, 1), 'Gastos e Ingresos 2026'!$A:$A, "<"&DATE(2026, 6, 1)), "") | L7: =IF(COUNTIFS('Gastos e Ingresos 2026'!$A:$A, ">="&DATE(2026, 5, 1), 'Gastos e Ingresos 2026'!$A:$A, "<"&DATE(2026, 6, 1))>0, SUMIFS('Gastos e Ingresos 2026'!$E:$E, 'Gastos e Ingresos 2026'!$D:$D, "Gasto", 'Gastos e Ingresos 2026'!$C:$C, L$2, 'Gastos e Ingresos 2026'!$A:$A, ">="&DATE(2026, 5, 1), 'Gastos e Ingresos 2026'!$A:$A, "<"&DATE(2026, 6, 1)), "") | M7: =IF(COUNTIFS('Gastos e Ingresos 2026'!$A:$A, ">="&DATE(2026, 5, 1), 'Gastos e Ingresos 2026'!$A:$A, "<"&DATE(2026, 6, 1))>0, SUMIFS('Gastos e Ingresos 2026'!$E:$E, 'Gastos e Ingresos 2026'!$D:$D, "Gasto", 'Gastos e Ingresos 2026'!$C:$C, M$2, 'Gastos e Ingresos 2026'!$A:$A, ">="&DATE(2026, 5, 1), 'Gastos e Ingresos 2026'!$A:$A, "<"&DATE(2026, 6, 1)), "") | ... R7: =IF(COUNTIFS('Gastos e Ingresos 2026'!$A:$A, ">="&DATE(2026, 5, 1), 'Gastos e Ingresos 2026'!$A:$A, "<"&DATE(2026, 6, 1))>0, SUMIFS('Gastos e Ingresos 2026'!$E:$E, 'Gastos e Ingresos 2026'!$D:$D, "Gasto", 'Gastos e Ingresos 2026'!$C:$C, R$2, 'Gastos e Ingresos 2026'!$A:$A, ">="&DATE(2026, 5, 1), 'Gastos e Ingresos 2026'!$A:$A, "<"&DATE(2026, 6, 1)), "")
A8: Junio | B8: =IF(COUNTIFS('Gastos e Ingresos 2026'!$A:$A, ">="&DATE(2026, 6, 1), 'Gastos e Ingresos 2026'!$A:$A, "<"&DATE(2026, 7, 1))>0, SUMIFS('Gastos e Ingresos 2026'!$E:$E, 'Gastos e Ingresos 2026'!$D:$D, "Ingreso", 'Gastos e Ingresos 2026'!$A:$A, ">="&DATE(2026, 6, 1), 'Gastos e Ingresos 2026'!$A:$A, "<"&DATE(2026, 7, 1)), "") | C8: =IF(COUNTIFS('Gastos e Ingresos 2026'!$A:$A, ">="&DATE(2026, 6, 1), 'Gastos e Ingresos 2026'!$A:$A, "<"&DATE(2026, 7, 1))>0, SUMIFS('Gastos e Ingresos 2026'!$E:$E, 'Gastos e Ingresos 2026'!$D:$D, "Gasto", 'Gastos e Ingresos 2026'!$A:$A, ">="&DATE(2026, 6, 1), 'Gastos e Ingresos 2026'!$A:$A, "<"&DATE(2026, 7, 1)), "") | D8: =IF(B8="","",B8-C8) | E8: =IF(B8="","",IF(B8>0, D8/B8, 0)) | F8: =IF(COUNTIFS('Gastos e Ingresos 2026'!$A:$A, ">="&DATE(2026, 6, 1), 'Gastos e Ingresos 2026'!$A:$A, "<"&DATE(2026, 7, 1))>0, SUMIFS('Gastos e Ingresos 2026'!$E:$E, 'Gastos e Ingresos 2026'!$D:$D, "Gasto", 'Gastos e Ingresos 2026'!$C:$C, F$2, 'Gastos e Ingresos 2026'!$A:$A, ">="&DATE(2026, 6, 1), 'Gastos e Ingresos 2026'!$A:$A, "<"&DATE(2026, 7, 1)), "") | G8: =IF(COUNTIFS('Gastos e Ingresos 2026'!$A:$A, ">="&DATE(2026, 6, 1), 'Gastos e Ingresos 2026'!$A:$A, "<"&DATE(2026, 7, 1))>0, SUMIFS('Gastos e Ingresos 2026'!$E:$E, 'Gastos e Ingresos 2026'!$D:$D, "Gasto", 'Gastos e Ingresos 2026'!$C:$C, G$2, 'Gastos e Ingresos 2026'!$A:$A, ">="&DATE(2026, 6, 1), 'Gastos e Ingresos 2026'!$A:$A, "<"&DATE(2026, 7, 1)), "") | H8: =IF(COUNTIFS('Gastos e Ingresos 2026'!$A:$A, ">="&DATE(2026, 6, 1), 'Gastos e Ingresos 2026'!$A:$A, "<"&DATE(2026, 7, 1))>0, SUMIFS('Gastos e Ingresos 2026'!$E:$E, 'Gastos e Ingresos 2026'!$D:$D, "Gasto", 'Gastos e Ingresos 2026'!$C:$C, H$2, 'Gastos e Ingresos 2026'!$A:$A, ">="&DATE(2026, 6, 1), 'Gastos e Ingresos 2026'!$A:$A, "<"&DATE(2026, 7, 1)), "") | I8: =IF(COUNTIFS('Gastos e Ingresos 2026'!$A:$A, ">="&DATE(2026, 6, 1), 'Gastos e Ingresos 2026'!$A:$A, "<"&DATE(2026, 7, 1))>0, SUMIFS('Gastos e Ingresos 2026'!$E:$E, 'Gastos e Ingresos 2026'!$D:$D, "Gasto", 'Gastos e Ingresos 2026'!$C:$C, I$2, 'Gastos e Ingresos 2026'!$A:$A, ">="&DATE(2026, 6, 1), 'Gastos e Ingresos 2026'!$A:$A, "<"&DATE(2026, 7, 1)), "") | J8: =IF(COUNTIFS('Gastos e Ingresos 2026'!$A:$A, ">="&DATE(2026, 6, 1), 'Gastos e Ingresos 2026'!$A:$A, "<"&DATE(2026, 7, 1))>0, SUMIFS('Gastos e Ingresos 2026'!$E:$E, 'Gastos e Ingresos 2026'!$D:$D, "Gasto", 'Gastos e Ingresos 2026'!$C:$C, J$2, 'Gastos e Ingresos 2026'!$A:$A, ">="&DATE(2026, 6, 1), 'Gastos e Ingresos 2026'!$A:$A, "<"&DATE(2026, 7, 1)), "") | K8: =IF(COUNTIFS('Gastos e Ingresos 2026'!$A:$A, ">="&DATE(2026, 6, 1), 'Gastos e Ingresos 2026'!$A:$A, "<"&DATE(2026, 7, 1))>0, SUMIFS('Gastos e Ingresos 2026'!$E:$E, 'Gastos e Ingresos 2026'!$D:$D, "Gasto", 'Gastos e Ingresos 2026'!$C:$C, K$2, 'Gastos e Ingresos 2026'!$A:$A, ">="&DATE(2026, 6, 1), 'Gastos e Ingresos 2026'!$A:$A, "<"&DATE(2026, 7, 1)), "") | L8: =IF(COUNTIFS('Gastos e Ingresos 2026'!$A:$A, ">="&DATE(2026, 6, 1), 'Gastos e Ingresos 2026'!$A:$A, "<"&DATE(2026, 7, 1))>0, SUMIFS('Gastos e Ingresos 2026'!$E:$E, 'Gastos e Ingresos 2026'!$D:$D, "Gasto", 'Gastos e Ingresos 2026'!$C:$C, L$2, 'Gastos e Ingresos 2026'!$A:$A, ">="&DATE(2026, 6, 1), 'Gastos e Ingresos 2026'!$A:$A, "<"&DATE(2026, 7, 1)), "") | M8: =IF(COUNTIFS('Gastos e Ingresos 2026'!$A:$A, ">="&DATE(2026, 6, 1), 'Gastos e Ingresos 2026'!$A:$A, "<"&DATE(2026, 7, 1))>0, SUMIFS('Gastos e Ingresos 2026'!$E:$E, 'Gastos e Ingresos 2026'!$D:$D, "Gasto", 'Gastos e Ingresos 2026'!$C:$C, M$2, 'Gastos e Ingresos 2026'!$A:$A, ">="&DATE(2026, 6, 1), 'Gastos e Ingresos 2026'!$A:$A, "<"&DATE(2026, 7, 1)), "") | ... R8: =IF(COUNTIFS('Gastos e Ingresos 2026'!$A:$A, ">="&DATE(2026, 6, 1), 'Gastos e Ingresos 2026'!$A:$A, "<"&DATE(2026, 7, 1))>0, SUMIFS('Gastos e Ingresos 2026'!$E:$E, 'Gastos e Ingresos 2026'!$D:$D, "Gasto", 'Gastos e Ingresos 2026'!$C:$C, R$2, 'Gastos e Ingresos 2026'!$A:$A, ">="&DATE(2026, 6, 1), 'Gastos e Ingresos 2026'!$A:$A, "<"&DATE(2026, 7, 1)), "")
A9: Julio | B9: =IF(COUNTIFS('Gastos e Ingresos 2026'!$A:$A, ">="&DATE(2026, 7, 1), 'Gastos e Ingresos 2026'!$A:$A, "<"&DATE(2026, 8, 1))>0, SUMIFS('Gastos e Ingresos 2026'!$E:$E, 'Gastos e Ingresos 2026'!$D:$D, "Ingreso", 'Gastos e Ingresos 2026'!$A:$A, ">="&DATE(2026, 7, 1), 'Gastos e Ingresos 2026'!$A:$A, "<"&DATE(2026, 8, 1)), "") | C9: =IF(COUNTIFS('Gastos e Ingresos 2026'!$A:$A, ">="&DATE(2026, 7, 1), 'Gastos e Ingresos 2026'!$A:$A, "<"&DATE(2026, 8, 1))>0, SUMIFS('Gastos e Ingresos 2026'!$E:$E, 'Gastos e Ingresos 2026'!$D:$D, "Gasto", 'Gastos e Ingresos 2026'!$A:$A, ">="&DATE(2026, 7, 1), 'Gastos e Ingresos 2026'!$A:$A, "<"&DATE(2026, 8, 1)), "") | D9: =IF(B9="","",B9-C9) | E9: =IF(B9="","",IF(B9>0, D9/B9, 0)) | F9: =IF(COUNTIFS('Gastos e Ingresos 2026'!$A:$A, ">="&DATE(2026, 7, 1), 'Gastos e Ingresos 2026'!$A:$A, "<"&DATE(2026, 8, 1))>0, SUMIFS('Gastos e Ingresos 2026'!$E:$E, 'Gastos e Ingresos 2026'!$D:$D, "Gasto", 'Gastos e Ingresos 2026'!$C:$C, F$2, 'Gastos e Ingresos 2026'!$A:$A, ">="&DATE(2026, 7, 1), 'Gastos e Ingresos 2026'!$A:$A, "<"&DATE(2026, 8, 1)), "") | G9: =IF(COUNTIFS('Gastos e Ingresos 2026'!$A:$A, ">="&DATE(2026, 7, 1), 'Gastos e Ingresos 2026'!$A:$A, "<"&DATE(2026, 8, 1))>0, SUMIFS('Gastos e Ingresos 2026'!$E:$E, 'Gastos e Ingresos 2026'!$D:$D, "Gasto", 'Gastos e Ingresos 2026'!$C:$C, G$2, 'Gastos e Ingresos 2026'!$A:$A, ">="&DATE(2026, 7, 1), 'Gastos e Ingresos 2026'!$A:$A, "<"&DATE(2026, 8, 1)), "") | H9: =IF(COUNTIFS('Gastos e Ingresos 2026'!$A:$A, ">="&DATE(2026, 7, 1), 'Gastos e Ingresos 2026'!$A:$A, "<"&DATE(2026, 8, 1))>0, SUMIFS('Gastos e Ingresos 2026'!$E:$E, 'Gastos e Ingresos 2026'!$D:$D, "Gasto", 'Gastos e Ingresos 2026'!$C:$C, H$2, 'Gastos e Ingresos 2026'!$A:$A, ">="&DATE(2026, 7, 1), 'Gastos e Ingresos 2026'!$A:$A, "<"&DATE(2026, 8, 1)), "") | I9: =IF(COUNTIFS('Gastos e Ingresos 2026'!$A:$A, ">="&DATE(2026, 7, 1), 'Gastos e Ingresos 2026'!$A:$A, "<"&DATE(2026, 8, 1))>0, SUMIFS('Gastos e Ingresos 2026'!$E:$E, 'Gastos e Ingresos 2026'!$D:$D, "Gasto", 'Gastos e Ingresos 2026'!$C:$C, I$2, 'Gastos e Ingresos 2026'!$A:$A, ">="&DATE(2026, 7, 1), 'Gastos e Ingresos 2026'!$A:$A, "<"&DATE(2026, 8, 1)), "") | J9: =IF(COUNTIFS('Gastos e Ingresos 2026'!$A:$A, ">="&DATE(2026, 7, 1), 'Gastos e Ingresos 2026'!$A:$A, "<"&DATE(2026, 8, 1))>0, SUMIFS('Gastos e Ingresos 2026'!$E:$E, 'Gastos e Ingresos 2026'!$D:$D, "Gasto", 'Gastos e Ingresos 2026'!$C:$C, J$2, 'Gastos e Ingresos 2026'!$A:$A, ">="&DATE(2026, 7, 1), 'Gastos e Ingresos 2026'!$A:$A, "<"&DATE(2026, 8, 1)), "") | K9: =IF(COUNTIFS('Gastos e Ingresos 2026'!$A:$A, ">="&DATE(2026, 7, 1), 'Gastos e Ingresos 2026'!$A:$A, "<"&DATE(2026, 8, 1))>0, SUMIFS('Gastos e Ingresos 2026'!$E:$E, 'Gastos e Ingresos 2026'!$D:$D, "Gasto", 'Gastos e Ingresos 2026'!$C:$C, K$2, 'Gastos e Ingresos 2026'!$A:$A, ">="&DATE(2026, 7, 1), 'Gastos e Ingresos 2026'!$A:$A, "<"&DATE(2026, 8, 1)), "") | L9: =IF(COUNTIFS('Gastos e Ingresos 2026'!$A:$A, ">="&DATE(2026, 7, 1), 'Gastos e Ingresos 2026'!$A:$A, "<"&DATE(2026, 8, 1))>0, SUMIFS('Gastos e Ingresos 2026'!$E:$E, 'Gastos e Ingresos 2026'!$D:$D, "Gasto", 'Gastos e Ingresos 2026'!$C:$C, L$2, 'Gastos e Ingresos 2026'!$A:$A, ">="&DATE(2026, 7, 1), 'Gastos e Ingresos 2026'!$A:$A, "<"&DATE(2026, 8, 1)), "") | M9: =IF(COUNTIFS('Gastos e Ingresos 2026'!$A:$A, ">="&DATE(2026, 7, 1), 'Gastos e Ingresos 2026'!$A:$A, "<"&DATE(2026, 8, 1))>0, SUMIFS('Gastos e Ingresos 2026'!$E:$E, 'Gastos e Ingresos 2026'!$D:$D, "Gasto", 'Gastos e Ingresos 2026'!$C:$C, M$2, 'Gastos e Ingresos 2026'!$A:$A, ">="&DATE(2026, 7, 1), 'Gastos e Ingresos 2026'!$A:$A, "<"&DATE(2026, 8, 1)), "") | ... R9: =IF(COUNTIFS('Gastos e Ingresos 2026'!$A:$A, ">="&DATE(2026, 7, 1), 'Gastos e Ingresos 2026'!$A:$A, "<"&DATE(2026, 8, 1))>0, SUMIFS('Gastos e Ingresos 2026'!$E:$E, 'Gastos e Ingresos 2026'!$D:$D, "Gasto", 'Gastos e Ingresos 2026'!$C:$C, R$2, 'Gastos e Ingresos 2026'!$A:$A, ">="&DATE(2026, 7, 1), 'Gastos e Ingresos 2026'!$A:$A, "<"&DATE(2026, 8, 1)), "")
A10: Agosto | B10: =IF(COUNTIFS('Gastos e Ingresos 2026'!$A:$A, ">="&DATE(2026, 8, 1), 'Gastos e Ingresos 2026'!$A:$A, "<"&DATE(2026, 9, 1))>0, SUMIFS('Gastos e Ingresos 2026'!$E:$E, 'Gastos e Ingresos 2026'!$D:$D, "Ingreso", 'Gastos e Ingresos 2026'!$A:$A, ">="&DATE(2026, 8, 1), 'Gastos e Ingresos 2026'!$A:$A, "<"&DATE(2026, 9, 1)), "") | C10: =IF(COUNTIFS('Gastos e Ingresos 2026'!$A:$A, ">="&DATE(2026, 8, 1), 'Gastos e Ingresos 2026'!$A:$A, "<"&DATE(2026, 9, 1))>0, SUMIFS('Gastos e Ingresos 2026'!$E:$E, 'Gastos e Ingresos 2026'!$D:$D, "Gasto", 'Gastos e Ingresos 2026'!$A:$A, ">="&DATE(2026, 8, 1), 'Gastos e Ingresos 2026'!$A:$A, "<"&DATE(2026, 9, 1)), "") | D10: =IF(B10="","",B10-C10) | E10: =IF(B10="","",IF(B10>0, D10/B10, 0)) | F10: =IF(COUNTIFS('Gastos e Ingresos 2026'!$A:$A, ">="&DATE(2026, 8, 1), 'Gastos e Ingresos 2026'!$A:$A, "<"&DATE(2026, 9, 1))>0, SUMIFS('Gastos e Ingresos 2026'!$E:$E, 'Gastos e Ingresos 2026'!$D:$D, "Gasto", 'Gastos e Ingresos 2026'!$C:$C, F$2, 'Gastos e Ingresos 2026'!$A:$A, ">="&DATE(2026, 8, 1), 'Gastos e Ingresos 2026'!$A:$A, "<"&DATE(2026, 9, 1)), "") | G10: =IF(COUNTIFS('Gastos e Ingresos 2026'!$A:$A, ">="&DATE(2026, 8, 1), 'Gastos e Ingresos 2026'!$A:$A, "<"&DATE(2026, 9, 1))>0, SUMIFS('Gastos e Ingresos 2026'!$E:$E, 'Gastos e Ingresos 2026'!$D:$D, "Gasto", 'Gastos e Ingresos 2026'!$C:$C, G$2, 'Gastos e Ingresos 2026'!$A:$A, ">="&DATE(2026, 8, 1), 'Gastos e Ingresos 2026'!$A:$A, "<"&DATE(2026, 9, 1)), "") | H10: =IF(COUNTIFS('Gastos e Ingresos 2026'!$A:$A, ">="&DATE(2026, 8, 1), 'Gastos e Ingresos 2026'!$A:$A, "<"&DATE(2026, 9, 1))>0, SUMIFS('Gastos e Ingresos 2026'!$E:$E, 'Gastos e Ingresos 2026'!$D:$D, "Gasto", 'Gastos e Ingresos 2026'!$C:$C, H$2, 'Gastos e Ingresos 2026'!$A:$A, ">="&DATE(2026, 8, 1), 'Gastos e Ingresos 2026'!$A:$A, "<"&DATE(2026, 9, 1)), "") | I10: =IF(COUNTIFS('Gastos e Ingresos 2026'!$A:$A, ">="&DATE(2026, 8, 1), 'Gastos e Ingresos 2026'!$A:$A, "<"&DATE(2026, 9, 1))>0, SUMIFS('Gastos e Ingresos 2026'!$E:$E, 'Gastos e Ingresos 2026'!$D:$D, "Gasto", 'Gastos e Ingresos 2026'!$C:$C, I$2, 'Gastos e Ingresos 2026'!$A:$A, ">="&DATE(2026, 8, 1), 'Gastos e Ingresos 2026'!$A:$A, "<"&DATE(2026, 9, 1)), "") | J10: =IF(COUNTIFS('Gastos e Ingresos 2026'!$A:$A, ">="&DATE(2026, 8, 1), 'Gastos e Ingresos 2026'!$A:$A, "<"&DATE(2026, 9, 1))>0, SUMIFS('Gastos e Ingresos 2026'!$E:$E, 'Gastos e Ingresos 2026'!$D:$D, "Gasto", 'Gastos e Ingresos 2026'!$C:$C, J$2, 'Gastos e Ingresos 2026'!$A:$A, ">="&DATE(2026, 8, 1), 'Gastos e Ingresos 2026'!$A:$A, "<"&DATE(2026, 9, 1)), "") | K10: =IF(COUNTIFS('Gastos e Ingresos 2026'!$A:$A, ">="&DATE(2026, 8, 1), 'Gastos e Ingresos 2026'!$A:$A, "<"&DATE(2026, 9, 1))>0, SUMIFS('Gastos e Ingresos 2026'!$E:$E, 'Gastos e Ingresos 2026'!$D:$D, "Gasto", 'Gastos e Ingresos 2026'!$C:$C, K$2, 'Gastos e Ingresos 2026'!$A:$A, ">="&DATE(2026, 8, 1), 'Gastos e Ingresos 2026'!$A:$A, "<"&DATE(2026, 9, 1)), "") | L10: =IF(COUNTIFS('Gastos e Ingresos 2026'!$A:$A, ">="&DATE(2026, 8, 1), 'Gastos e Ingresos 2026'!$A:$A, "<"&DATE(2026, 9, 1))>0, SUMIFS('Gastos e Ingresos 2026'!$E:$E, 'Gastos e Ingresos 2026'!$D:$D, "Gasto", 'Gastos e Ingresos 2026'!$C:$C, L$2, 'Gastos e Ingresos 2026'!$A:$A, ">="&DATE(2026, 8, 1), 'Gastos e Ingresos 2026'!$A:$A, "<"&DATE(2026, 9, 1)), "") | M10: =IF(COUNTIFS('Gastos e Ingresos 2026'!$A:$A, ">="&DATE(2026, 8, 1), 'Gastos e Ingresos 2026'!$A:$A, "<"&DATE(2026, 9, 1))>0, SUMIFS('Gastos e Ingresos 2026'!$E:$E, 'Gastos e Ingresos 2026'!$D:$D, "Gasto", 'Gastos e Ingresos 2026'!$C:$C, M$2, 'Gastos e Ingresos 2026'!$A:$A, ">="&DATE(2026, 8, 1), 'Gastos e Ingresos 2026'!$A:$A, "<"&DATE(2026, 9, 1)), "") | ... R10: =IF(COUNTIFS('Gastos e Ingresos 2026'!$A:$A, ">="&DATE(2026, 8, 1), 'Gastos e Ingresos 2026'!$A:$A, "<"&DATE(2026, 9, 1))>0, SUMIFS('Gastos e Ingresos 2026'!$E:$E, 'Gastos e Ingresos 2026'!$D:$D, "Gasto", 'Gastos e Ingresos 2026'!$C:$C, R$2, 'Gastos e Ingresos 2026'!$A:$A, ">="&DATE(2026, 8, 1), 'Gastos e Ingresos 2026'!$A:$A, "<"&DATE(2026, 9, 1)), "")
